[2024-06-01T18:18:02.357+0000] {local_task_job_runner.py:120} INFO - ::group::Pre task execution logs
[2024-06-01T18:18:02.378+0000] {taskinstance.py:2076} INFO - Dependencies all met for dep_context=non-requeueable deps ti=<TaskInstance: covid19_project_dag.get_data manual__2024-06-01T18:15:57.328063+00:00 [queued]>
[2024-06-01T18:18:02.562+0000] {taskinstance.py:2076} INFO - Dependencies all met for dep_context=requeueable deps ti=<TaskInstance: covid19_project_dag.get_data manual__2024-06-01T18:15:57.328063+00:00 [queued]>
[2024-06-01T18:18:02.563+0000] {taskinstance.py:2306} INFO - Starting attempt 2 of 3
[2024-06-01T18:18:02.588+0000] {taskinstance.py:2330} INFO - Executing <Task(PythonOperator): get_data> on 2024-06-01 18:15:57.328063+00:00
[2024-06-01T18:18:02.592+0000] {warnings.py:110} WARNING - /home/***/.local/lib/python3.12/site-packages/***/task/task_runner/standard_task_runner.py:61: DeprecationWarning: This process (pid=256) is multi-threaded, use of fork() may lead to deadlocks in the child.
  pid = os.fork()

[2024-06-01T18:18:02.594+0000] {standard_task_runner.py:90} INFO - Running: ['***', 'tasks', 'run', 'covid19_project_dag', 'get_data', 'manual__2024-06-01T18:15:57.328063+00:00', '--job-id', '32', '--raw', '--subdir', 'DAGS_FOLDER/covid19_project_dag.py', '--cfg-path', '/tmp/tmpja54m2u3']
[2024-06-01T18:18:02.596+0000] {standard_task_runner.py:63} INFO - Started process 258 to run task
[2024-06-01T18:18:02.597+0000] {standard_task_runner.py:91} INFO - Job 32: Subtask get_data
[2024-06-01T18:18:02.643+0000] {task_command.py:426} INFO - Running <TaskInstance: covid19_project_dag.get_data manual__2024-06-01T18:15:57.328063+00:00 [running]> on host b18befda89c1
[2024-06-01T18:18:02.743+0000] {taskinstance.py:2648} INFO - Exporting env vars: AIRFLOW_CTX_DAG_OWNER='kelvin' AIRFLOW_CTX_DAG_ID='covid19_project_dag' AIRFLOW_CTX_TASK_ID='get_data' AIRFLOW_CTX_EXECUTION_DATE='2024-06-01T18:15:57.328063+00:00' AIRFLOW_CTX_TRY_NUMBER='2' AIRFLOW_CTX_DAG_RUN_ID='manual__2024-06-01T18:15:57.328063+00:00'
[2024-06-01T18:18:02.745+0000] {taskinstance.py:430} INFO - ::endgroup::
[2024-06-01T18:18:02.925+0000] {taskinstance.py:441} INFO - ::group::Post task execution logs
[2024-06-01T18:18:02.926+0000] {taskinstance.py:2905} ERROR - Task failed with exception
Traceback (most recent call last):
  File "/home/airflow/.local/lib/python3.12/site-packages/urllib3/connectionpool.py", line 467, in _make_request
    self._validate_conn(conn)
  File "/home/airflow/.local/lib/python3.12/site-packages/urllib3/connectionpool.py", line 1099, in _validate_conn
    conn.connect()
  File "/home/airflow/.local/lib/python3.12/site-packages/urllib3/connection.py", line 653, in connect
    sock_and_verified = _ssl_wrap_socket_and_match_hostname(
                        ^^^^^^^^^^^^^^^^^^^^^^^^^^^^^^^^^^^^
  File "/home/airflow/.local/lib/python3.12/site-packages/urllib3/connection.py", line 806, in _ssl_wrap_socket_and_match_hostname
    ssl_sock = ssl_wrap_socket(
               ^^^^^^^^^^^^^^^^
  File "/home/airflow/.local/lib/python3.12/site-packages/urllib3/util/ssl_.py", line 465, in ssl_wrap_socket
    ssl_sock = _ssl_wrap_socket_impl(sock, context, tls_in_tls, server_hostname)
               ^^^^^^^^^^^^^^^^^^^^^^^^^^^^^^^^^^^^^^^^^^^^^^^^^^^^^^^^^^^^^^^^^
  File "/home/airflow/.local/lib/python3.12/site-packages/urllib3/util/ssl_.py", line 509, in _ssl_wrap_socket_impl
    return ssl_context.wrap_socket(sock, server_hostname=server_hostname)
           ^^^^^^^^^^^^^^^^^^^^^^^^^^^^^^^^^^^^^^^^^^^^^^^^^^^^^^^^^^^^^^
  File "/usr/local/lib/python3.12/ssl.py", line 455, in wrap_socket
    return self.sslsocket_class._create(
           ^^^^^^^^^^^^^^^^^^^^^^^^^^^^^
  File "/usr/local/lib/python3.12/ssl.py", line 1042, in _create
    self.do_handshake()
  File "/usr/local/lib/python3.12/ssl.py", line 1320, in do_handshake
    self._sslobj.do_handshake()
ssl.SSLEOFError: [SSL: UNEXPECTED_EOF_WHILE_READING] EOF occurred in violation of protocol (_ssl.c:1000)

During handling of the above exception, another exception occurred:

Traceback (most recent call last):
  File "/home/airflow/.local/lib/python3.12/site-packages/urllib3/connectionpool.py", line 793, in urlopen
    response = self._make_request(
               ^^^^^^^^^^^^^^^^^^^
  File "/home/airflow/.local/lib/python3.12/site-packages/urllib3/connectionpool.py", line 491, in _make_request
    raise new_e
urllib3.exceptions.SSLError: [SSL: UNEXPECTED_EOF_WHILE_READING] EOF occurred in violation of protocol (_ssl.c:1000)

The above exception was the direct cause of the following exception:

Traceback (most recent call last):
  File "/home/airflow/.local/lib/python3.12/site-packages/requests/adapters.py", line 486, in send
    resp = conn.urlopen(
           ^^^^^^^^^^^^^
  File "/home/airflow/.local/lib/python3.12/site-packages/urllib3/connectionpool.py", line 847, in urlopen
    retries = retries.increment(
              ^^^^^^^^^^^^^^^^^^
  File "/home/airflow/.local/lib/python3.12/site-packages/urllib3/util/retry.py", line 515, in increment
    raise MaxRetryError(_pool, url, reason) from reason  # type: ignore[arg-type]
    ^^^^^^^^^^^^^^^^^^^^^^^^^^^^^^^^^^^^^^^^^^^^^^^^^^^
urllib3.exceptions.MaxRetryError: HTTPSConnectionPool(host='api.data.gov.my', port=443): Max retries exceeded with url: /data-catalogue?id=covid_cases&limit=1 (Caused by SSLError(SSLEOFError(8, '[SSL: UNEXPECTED_EOF_WHILE_READING] EOF occurred in violation of protocol (_ssl.c:1000)')))

During handling of the above exception, another exception occurred:

Traceback (most recent call last):
  File "/home/airflow/.local/lib/python3.12/site-packages/airflow/models/taskinstance.py", line 465, in _execute_task
    result = _execute_callable(context=context, **execute_callable_kwargs)
             ^^^^^^^^^^^^^^^^^^^^^^^^^^^^^^^^^^^^^^^^^^^^^^^^^^^^^^^^^^^^^
  File "/home/airflow/.local/lib/python3.12/site-packages/airflow/models/taskinstance.py", line 432, in _execute_callable
    return execute_callable(context=context, **execute_callable_kwargs)
           ^^^^^^^^^^^^^^^^^^^^^^^^^^^^^^^^^^^^^^^^^^^^^^^^^^^^^^^^^^^^
  File "/home/airflow/.local/lib/python3.12/site-packages/airflow/models/baseoperator.py", line 400, in wrapper
    return func(self, *args, **kwargs)
           ^^^^^^^^^^^^^^^^^^^^^^^^^^^
  File "/home/airflow/.local/lib/python3.12/site-packages/airflow/operators/python.py", line 235, in execute
    return_value = self.execute_callable()
                   ^^^^^^^^^^^^^^^^^^^^^^^
  File "/home/airflow/.local/lib/python3.12/site-packages/airflow/operators/python.py", line 252, in execute_callable
    return self.python_callable(*self.op_args, **self.op_kwargs)
           ^^^^^^^^^^^^^^^^^^^^^^^^^^^^^^^^^^^^^^^^^^^^^^^^^^^^^
  File "/opt/airflow/dags/covid19_project_dag.py", line 22, in get_daily_data
    response_json = requests.get(url=url).json()
                    ^^^^^^^^^^^^^^^^^^^^^
  File "/home/airflow/.local/lib/python3.12/site-packages/requests/api.py", line 73, in get
    return request("get", url, params=params, **kwargs)
           ^^^^^^^^^^^^^^^^^^^^^^^^^^^^^^^^^^^^^^^^^^^^
  File "/home/airflow/.local/lib/python3.12/site-packages/requests/api.py", line 59, in request
    return session.request(method=method, url=url, **kwargs)
           ^^^^^^^^^^^^^^^^^^^^^^^^^^^^^^^^^^^^^^^^^^^^^^^^^
  File "/home/airflow/.local/lib/python3.12/site-packages/requests/sessions.py", line 589, in request
    resp = self.send(prep, **send_kwargs)
           ^^^^^^^^^^^^^^^^^^^^^^^^^^^^^^
  File "/home/airflow/.local/lib/python3.12/site-packages/requests/sessions.py", line 703, in send
    r = adapter.send(request, **kwargs)
        ^^^^^^^^^^^^^^^^^^^^^^^^^^^^^^^
  File "/home/airflow/.local/lib/python3.12/site-packages/requests/adapters.py", line 517, in send
    raise SSLError(e, request=request)
requests.exceptions.SSLError: HTTPSConnectionPool(host='api.data.gov.my', port=443): Max retries exceeded with url: /data-catalogue?id=covid_cases&limit=1 (Caused by SSLError(SSLEOFError(8, '[SSL: UNEXPECTED_EOF_WHILE_READING] EOF occurred in violation of protocol (_ssl.c:1000)')))
[2024-06-01T18:18:02.944+0000] {taskinstance.py:1206} INFO - Marking task as UP_FOR_RETRY. dag_id=covid19_project_dag, task_id=get_data, run_id=manual__2024-06-01T18:15:57.328063+00:00, execution_date=20240601T181557, start_date=20240601T181802, end_date=20240601T181802
[2024-06-01T18:18:02.968+0000] {standard_task_runner.py:110} ERROR - Failed to execute job 32 for task get_data (HTTPSConnectionPool(host='api.data.gov.my', port=443): Max retries exceeded with url: /data-catalogue?id=covid_cases&limit=1 (Caused by SSLError(SSLEOFError(8, '[SSL: UNEXPECTED_EOF_WHILE_READING] EOF occurred in violation of protocol (_ssl.c:1000)'))); 258)
[2024-06-01T18:18:03.011+0000] {local_task_job_runner.py:240} INFO - Task exited with return code 1
[2024-06-01T18:18:03.031+0000] {taskinstance.py:3498} INFO - 0 downstream tasks scheduled from follow-on schedule check
[2024-06-01T18:18:03.032+0000] {local_task_job_runner.py:222} INFO - ::endgroup::
